# 예외 처리하기
## try-catch문
### 예외를 처리하는 가장 기본 문법인 try-catch문의 형식은 다음과 같다.
```java
try {
    예외가 발생할 수 있는 코드
} catch(처리할 예외 타입 e) {
    try 블록 안에서 예외가 발생했을 때 예외를 처리하는 부분
}
```
### try 블록에는 예외가 발생할 가능성이 있는 코드를 작성한다.
### 만약 try 블록 안에서 예외가 발생하면 바로 catch 블록이 수행된다.
### catch문의 괄호 안에 쓰는 예외 타입은 예외 상황에 따라 달라진다.
## try-catch문 사용하기
### 다음은 요소가 5개인 정수형 배열을 만들고 요소에 0부터 4를 대입하는 코드이다.
```java
int[] arr = new int[5];

for(int i = 0; i < 5; i++) {
    arr[i] = i;
    System.out.println(arr[i]);
}
```
### 배열 크기가 5이므로 5개를 저장할 수 있다.
### 하지만 여기서 i < 5를 i <= 5로 바꾸면 예외상황이 발생한다.
```java
int[] arr = new int[5];
    
    for(int i = 0; i <= 5; i++) {
        arr[i] = i;
        System.out.println(arr[i]);
    }
}
```
> 0\
1\
2\
3\
4\
Exception in thread "main" java.lang.ArrayIndexOutOfBoundsException: Index 5 out of bounds for length 5
	at exception.ArrayExceptionHandling.main(ArrayExceptionHandling.java:8)
### 배열에 저장하려는 값의 개수가 배열 범위를 벗어났기 때문에 예외가 발생한 것이다.
### 참고로 이 예외는 RuntimeException의 하위 클래스인 ArrayIndexOutOfBoundsException으로 처리하는데, 이 클래스는 예외 처리를 하지 않아도 컴파일 오류가 나지 않는다.
### 따라서 프로그래머가 직접 예외 처리를 하지 않으면 예외가 잡히지 않아서 예외가 발생하는 순간게 프로그램이 갑자기 멈춘다.
### 그러므로 예외가 발생한 순간 프로그램이 비정상 종료되지 않도록 예외 처리를 해줘야 한다.
```java
package exception;

public class ArrayExceptionHandling {
	public static void main(String[] args) {
		int[] arr = new int[5];
		
		try {
			for(int i = 0; i <= 5; i++) {
				arr[i] = i;
				System.out.println(arr[i]);
			}
		} catch (ArrayIndexOutOfBoundsException e) {
			System.out.println(e);
			System.out.println("예외 처리 부분");
		}
		System.out.println("프로그램 종료");
	}
}
```
> 0\
1\
2\
3\
4\
java.lang.ArrayIndexOutOfBoundsException: Index 5 out of bounds for length 5\
예외 처리 부분\
프로그램 종료
### 발생한 예외는 catch 블록에서 처리하므로 System.out.println("프로그램 종료") 문장 까지 수행하고 프로그램이 정상 종료 된다.
### 만약 예외가 발생하여 프로그램이 바로 비정상 종료됐다면 System.out.println("프로그램 종료") 문장을 수행할 수 없다.
### 이처럼 예외 처리는 프로그램이 비정상 종료되는 것을 방지할 수 있으므로 매우 중요하다.
## 컴파일러에 의해 예외가 체크되는 경우
### 자바에서 파일을 읽고 쓰는 데 스트림 객체를 사용한다,
### 스트림 종류는 여러 가지가 있지만, 여기에서는 파일에서 데이터를 바이트 단위로 읽어 들이는 FileInputStream을 사용한다.
### exception 패키지를 만들고 ExceptionHandling1.java파일을 작성한다.
### main() 함수 안에 FileInputStream 선언 코드를 다음처럼 작성한다.
```java
FileInputStream fis = new FileInputStream("a.text");
```
### 위 코드는 a.text 파일에서 데이터를 읽어들이기 위해 스트림 객체를 생성한다는 의미이다.
### 허나 이렇게 코드를 작성하면 'FileNotFoundException이 처리되지 않았다'는 메시지가 나타난다.
### 이 경우에는 a.text 파일이 존재하지 않는 오류가 발생할 수 있다는 것이다.
### 읽으려는 파일이 없는 경우에 JVM에서는 FileNotFoundException 예외 클래스가 생성된다.
### 따라서 위 오류 메시지는 이러한 예외 상황에 대비한 예외 처리를 해야 한다는 뜻이다.
### 여기서 try-catch문으로 감싸는 것을 추가한다.
```java
try {
	FileInputStream fis = new FileInputStream("a.text");
} catch (FileNotFoundException e) {
	// TODO Auto-generated catch block
	e.printStackTrace();
}
```
### 위 코드를 실행 시키면 아직 a.text 파일이 없으므로 이 상황에선 당연히 다음처럼 예외가 발생한다.
> java.io.FileNotFoundException: a.text (지정된 파일을 찾을 수 없습니다)
	at java.base/java.io.FileInputStream.open0(Native Method)
	at java.base/java.io.FileInputStream.open(FileInputStream.java:219)
	at java.base/java.io.FileInputStream.<init>(FileInputStream.java:157)
	at java.base/java.io.FileInputStream.<init>(FileInputStream.java:112)
	at exception.ExceptionHandling1.main(ExceptionHandling1.java:9)
### try-catch를 이용해 완전히 코드를 완성시키자.
```java
package exception;

import java.io.FileInputStream;
import java.io.FileNotFoundException;

public class ExceptionHandling1 {
	public static void main(String[] args) {
		try {
			FileInputStream fis = new FileInputStream("a.text");
		} catch (FileNotFoundException e) {
			System.out.println(e);
		}
		System.out.println("여기도 수행됩니다.");
	}
}
```
> java.io.FileNotFoundException: a.text (지정된 파일을 찾을 수 없습니다)\
여기도 수행됩니다.
### 예외가 발생했을 때 FileNotFoundException e의 toString() 메서드가 호출되도록 코드를 장석해보았다.
### 출력 결과를 보면 첫 번째 줄은 e의 출력 내용이고, 두 번째 줄은 "여기도 수행됩니다."가 정상적으로 출력되었다.
### 만일 비정상 종료됐다면 두 번째 줄은 출력이 안됐을 것이다.
---
### 예외 처리를 한다고 해서 프로그램의 예외 상황 자체를 막을 수는 없으나, 예외 처리를 하면 예외 상황을 알려주는 메시지를 볼 수 있고 프로그램이 비정상 종료되지 않고 계속 수행되도록 만들 수 있다.
## try-catch-finally문
### 프로그램에서 사용한 리소스는 프로그램이 종료되면 자동으로 해제된다.
### 예를 들어 네트워크가 연결되었을 경우에 채팅 프로그램이 종료될 때 연결돋 닫힌다.
### 하지만 끝나지 않고 계속 수행되는 서비스 같은 경우에 리소스를 여러 번 반복해서 열기만 하고 닫지 않는다면 문제가 발생한다.
### 시스템에서 허용하는 지원은 한계가 있기 때문이다.
### 따라서 사용한 시스템 리소스는 사용 후 반드시 close() 메서드로 닫아주어야 한다.
### 앞에서 사용한 코드에 열어 놓은 파일 리소스를 닫는 코드를 다음과 같이 추가한다.
```java
try {
	fis = new FileInputStream("a.text");
	if(fis != null) {
		try {
			fis.close();	//try 블록에서 파일 리소스를 닫는 close() 메서드 호출
		} catch(IOException e) {
			e.printStackTrace();
		}
	}
}
```
### 현재는 try 블록에서만 파일 리소스를 닫았으나, 프로그램이 정상적으로 종료된 경우에도 열어 놓은 파일 리소스를 닫아야 하고, 비정상 종료된 경우에도 리소스를 닫아야 한다.
### 따라서 try 블록뿐 아니라 catch 블록에도 close() 메서드를 사용해야 한다.
---
### 만약 try 블록 안에서 발새할 수 있는 예외 상황이 여러 개라면 catch 블록을 예외 상황 수만큼 구현해야 한다.
### 그런데 한번 열어 놓은 리소스를 해제하는 코드를 try-catch-catch... 각 블록에 모두 작성해야 한다면 정말 번거로운 일이다.
### 이때 사용하는 블록이 바로 finally이다.
### finally를 사용하는 형식은 다음과 같다.
```java
try {
	예외가 발생할 수 있는 부분
} cahch(처리할 예외 타입 e) {
	예외를 처리하는 부분
} finally {
	항상 수행되는 부분
}
```
### 일단 try 블록이 수행되면 finally 블록은 어떤 경우에도 반드시 수행된다.
### 이를테면 try나 catch문에 return문이 있어도 수행한다.
### 따라서 try-catch-catch... 각 블록마다 리소스를 해제하지 않고 finally 블록에서 한 번만 해제해주면 된다.
```java
package exception;

import java.io.FileInputStream;
import java.io.FileNotFoundException;
import java.io.IOException;

public class ExceptionHandling2 {
	public static void main(String[] args) {
		FileInputStream fis = null;
		
		try {
			fis = new FileInputStream("a.text");
		} catch (FileNotFoundException e) {
			System.out.println(e);
			return;
		} finally {
			if(fis != null) {
				try {
					fis.close();	//파일 입력 스트림 닫기
				} catch (IOException e) {
					e.printStackTrace();
				}
			}
			System.out.println("항상 수행됩니다.");
		}
		System.out.println("여기도 수행됩니다.");
	}
}
```
> java.io.FileNotFoundException: a.text (지정된 파일을 찾을 수 없습니다)\
여기도 수행됩니다.
## try-with-resources문
### 시스템 리소스를 사용하고 해제하는 코드는 다소 복잡하다.
### 자바 7부터 try-with-resources문을 제공하여 close() 메서드를 명시적으로 호출하지 않아도 try 블록 내에서 열린 리소스를 자동으로 닫도록 만들 수 있다.
### try-with-resources 문법을 사용하려면 해당 리소스가 AutoCloseable 인터페이스를 구현해야 한다.
### AutoCloseable 인터페이스에는 close() 메서드가 있고 이를 구현한 클래스는 close()를 명시적으로 호출하지 않아도 close() 메서드 부분이 호출된다.
### FileInputStream 클래스를 JavaDoc에서 찾아보면 Closeable과 AutoCloseable 인터페이스를 구현한다.
### 따라서 자바 7부터는 try-with-resources 문법을 사용하면 FileInputStream을 사용할 때 close()를 명시적으로 호출하지 않아도 정상인 경우와 예외가 발생한 경우 모두 close() 메서드가 호출된다.
### FileInputStream 이외에 네트워크(socket)와 데이터베이스(connection) 관련 클래스도 AutoCloseable 인터페이스를 구현한다.
## AutoCloseable 인터페이스
### AutoCloseable 인터페이스를 직접 구현한 클래스를 만들고 프로그램이 정상적으로 수행됐을 때와 예외가 발생했을 때 각각 close() 메서드 부분이 잘 호출되는지 살펴보자.
### 먼저 프로그램이 정상적으로 수행되는 경우이다.
```java
package exception;

public class AutoCloseObj implements AutoCloseable {

	@Override
	public void close() throws Exception {	//close 메서드 구현
		System.out.println("리소스가 close() 되었습니다.");
	}
}
```
### AutoCloseable 인터페이스는 반드시 close() 메서드를 구현해야 한다.
### 시스템 리소스인 경우에는 파일 스트림을 닫거나 네트워크 연결을 해제하는 코드를 작성해야겠지만, 여기서는 close() 메서드가 제대로 호출되는지 알아보는 것이다.
---
### 이제 AutoCloseTest 클래스를 만들어 테스트해보자.
```java
package exception;

public class AutoCloseTest {
	public static void main(String[] args) {
		try(AutoCloseObj obj = new AutoCloseObj()) {	//사용할 리소스 선언
		} catch (Exception e) {
			System.out.println("예외 부분이다.");
		}
	}
}
```
> 리소스가 close() 되었습니다.
### try-with-resources문을 사용할 때 try문의 괄호 안에 리소스를 선언한다.
### 이 예제는 예외가 발생하지 않고 정상 종료되는데 출력 결과를 보면 close() 메서드가 호출된 것을 알 수 있다.
### 리소스를 여러 개 생성해야 한다면 세미콜론으로 구분한다.
```java
try(A a = new A(); B b = new B()) {
	...
} catch (Exception e) {
	...
}
```
---
### 예외가 발생하여 종료되는 경우에도 close() 메서드가 잘 호출되는지 살펴봐야 한다.
### throw new Exception() 문장을 사용하면 프로그램에서 강제로 예외를 발생시켜 catch 블록이 수행되도록 구현할 수 있다.
```java
package exception;

public class AutoCloseTest {
	public static void main(String[] args) {
		try(AutoCloseObj obj = new AutoCloseObj()) {	//사용할 리소스 선언
			throw new Exception();	//강제 예외 발생
		} catch (Exception e) {
			System.out.println("예외 부분이다.");
		}
	}
}
```
> 리소스가 close() 되었습니다.\
예외 부분이다.
### 강제로 예외를 발생시키면 catch 블록이 수행된다.
### 출력 결과를 보면 리소스의 close() 메서드가 먼저 호출되고 예외 블록 부분이 실행된 것을 알 수 있다.
### 이처럼 try-with-resources문을 사용하면 close() 메서드를 명시적으로 호출하지 않아도 정상 종료된 경우와 예외가 발생한 경우 모두 리소스가 잘 해제된다.
## 향상된 try-with-resources문(자바 9에서 추가된 문법)
### 자바 7에서 제공하기 시작한 try-with-resources문의 예외 처리 방법은 자바 9로 업그레이드 되면서 조금 더 향상되었다.
### 자바 7에서는 AutoCloseable 인터페이스를 구현한 리소스의 변수 선언을 try문 괄호 안에서 해야 했다.
### 따라서 리소스가 외부에 선언되고 생성된 경우에도 다른 참조 변수로 괄호 안에 다시 선언해야 했다.
```java
AutoCloseObj obj = new AutoCloseObj();
try (AutoClose obj2 = obj) {	//다른 참조변수 다시 선언
	throw new Exception();
} catch(Exception e) {
	System.out.println("예외 부분이다.");
}
```
### 하지만 자바 9부터는 다음처럼 try문의 괄호 안에서 외부에서 선언한 변수를 쓸 수 있다.
### 이렇게 사용하면 가독성도 좋고 반복하여 선언하는 일도 줄어든다.
```java
AutoCloseObj obj = new AutoCloseObj();
try (obj) {	//외부에서 선언한 변수를 그대로 쓸 수 있음
	throw new Exception();
} catch(Exception e) {
	System.out.println("예외 부분이다.");
}
```